<sdf version='1.6'>
  <world name='default'>
    <scene>
      <shadows>0</shadows>
      <ambient>0.4 0.4 0.4 1</ambient>
      <background>0.7 0.7 0.7 1</background>
    </scene>
    <light name='sun' type='directional'>
      <cast_shadows>1</cast_shadows>
      <pose frame=''>0 0 10 0 -0 0</pose>
      <diffuse>0.8 0.8 0.8 1</diffuse>
      <specular>0.2 0.2 0.2 1</specular>
      <attenuation>
        <range>1000</range>
        <constant>0.9</constant>
        <linear>0.01</linear>
        <quadratic>0.001</quadratic>
      </attenuation>
      <direction>-0.5 0.1 -0.9</direction>
    </light>
    <model name='ground_plane'>
      <static>1</static>
      <link name='link'>
        <collision name='collision'>
          <geometry>
            <plane>
              <normal>0 0 1</normal>
              <size>100 100</size>
            </plane>
          </geometry>
          <surface>
            <friction>
              <ode>
                <mu>100</mu>
                <mu2>50</mu2>
              </ode>
              <torsional>
                <ode/>
              </torsional>
            </friction>
            <contact>
              <ode/>
            </contact>
            <bounce/>
          </surface>
          <max_contacts>10</max_contacts>
        </collision>
        <visual name='visual'>
          <cast_shadows>0</cast_shadows>
          <geometry>
            <plane>
              <normal>0 0 1</normal>
              <size>100 100</size>
            </plane>
          </geometry>
          <material>
            <script>
              <uri>file://media/materials/scripts/gazebo.material</uri>
              <name>Gazebo/Grey</name>
            </script>
          </material>
        </visual>
        <self_collide>0</self_collide>
        <enable_wind>0</enable_wind>
        <kinematic>0</kinematic>
      </link>
    </model>
    <model name='ground_plane2'>
      <static>1</static>
      <link name='link'>
        <pose>0 0 -0.01 0 0 0</pose>
        <collision name='collision'>
          <geometry>
            <plane>
              <normal>0 0 1</normal>
              <size>100 100</size>
            </plane>
          </geometry>
          <surface>
            <friction>
              <ode>
                <mu>100</mu>
                <mu2>50</mu2>
              </ode>
              <torsional>
                <ode/>
              </torsional>
            </friction>
            <contact>
              <ode/>
            </contact>
            <bounce/>
          </surface>
          <max_contacts>10</max_contacts>
        </collision>
        <visual name='visual'>
          <cast_shadows>0</cast_shadows>
          <geometry>
            <plane>
              <normal>0 0 1</normal>
              <size>100 100</size>
            </plane>
          </geometry>
          <material>
            <script>
              <uri>file://media/materials/scripts/gazebo.material</uri>
              <name>Gazebo/Grey</name>
            </script>
          </material>
        </visual>
        <self_collide>0</self_collide>
        <enable_wind>0</enable_wind>
        <kinematic>0</kinematic>
      </link>
    </model>
    <model name='iris_lidar'>
      <link name='iris_demo::iris::base_link'>
        <velocity_decay>
          <linear>0</linear>
          <angular>0</angular>
        </velocity_decay>
        <inertial>
          <pose frame=''>0 0 0 0 -0 0</pose>
          <mass>1.5</mass>
          <inertia>
            <ixx>0.008</ixx>
            <ixy>0</ixy>
            <ixz>0</ixz>
            <iyy>0.015</iyy>
            <iyz>0</iyz>
            <izz>0.017</izz>
          </inertia>
        </inertial>
        <collision name='base_link_collision'>
          <pose frame=''>0 0 -0.08 0 -0 0</pose>
          <geometry>
            <box>
              <size>0.47 0.47 0.23</size>
            </box>
          </geometry>
          <surface>
            <contact>
              <ode>
                <max_vel>100</max_vel>
                <min_depth>0.001</min_depth>
              </ode>
            </contact>
            <friction>
              <ode>
                <mu>100000</mu>
                <mu2>100000</mu2>
              </ode>
              <torsional>
                <ode/>
              </torsional>
            </friction>
            <bounce/>
          </surface>
          <max_contacts>10</max_contacts>
        </collision>
        <visual name='base_link_visual'>
          <geometry>
            <mesh>
              <uri>model://iris_with_standoffs/meshes/iris.dae</uri>
            </mesh>
          </geometry>
          <material>
            <script>
              <name>Gazebo/DarkGrey</name>
              <uri>__default__</uri>
            </script>
          </material>
        </visual>
        <visual name='front_left_leg_visual'>
          <pose frame=''>0.123 0.22 -0.11 0 -0 0</pose>
          <geometry>
            <cylinder>
              <radius>0.005</radius>
              <length>0.17</length>
            </cylinder>
          </geometry>
          <material>
            <script>
              <name>Gazebo/FlatBlack</name>
              <uri>file://media/materials/scripts/gazebo.material</uri>
            </script>
          </material>
        </visual>
        <visual name='front_right_leg_visual'>
          <pose frame=''>0.123 -0.22 -0.11 0 -0 0</pose>
          <geometry>
            <cylinder>
              <radius>0.005</radius>
              <length>0.17</length>
            </cylinder>
          </geometry>
          <material>
            <script>
              <name>Gazebo/FlatBlack</name>
              <uri>file://media/materials/scripts/gazebo.material</uri>
            </script>
          </material>
        </visual>
        <visual name='rear_left_leg_visual'>
          <pose frame=''>-0.14 0.21 -0.11 0 -0 0</pose>
          <geometry>
            <cylinder>
              <radius>0.005</radius>
              <length>0.17</length>
            </cylinder>
          </geometry>
          <material>
            <script>
              <name>Gazebo/FlatBlack</name>
              <uri>file://media/materials/scripts/gazebo.material</uri>
            </script>
          </material>
        </visual>
        <visual name='rear_right_leg_visual'>
          <pose frame=''>-0.14 -0.21 -0.11 0 -0 0</pose>
          <geometry>
            <cylinder>
              <radius>0.005</radius>
              <length>0.17</length>
            </cylinder>
          </geometry>
          <material>
            <script>
              <name>Gazebo/FlatBlack</name>
              <uri>file://media/materials/scripts/gazebo.material</uri>
            </script>
          </material>
        </visual>
        <pose frame=''>0 0 0.194923 0 -0 0</pose>
        <self_collide>0</self_collide>
        <enable_wind>0</enable_wind>
        <kinematic>0</kinematic>
      </link>
      <link name='iris_demo::iris::iris/ground_truth/odometry_sensorgt_link'>
        <pose frame=''>0 0 0.194923 0 -0 0</pose>
        <inertial>
          <pose frame=''>0 0 0 0 -0 0</pose>
          <mass>0.15</mass>
          <inertia>
            <ixx>0.0001</ixx>
            <ixy>0</ixy>
            <ixz>0</ixz>
            <iyy>0.0002</iyy>
            <iyz>0</iyz>
            <izz>0.0002</izz>
          </inertia>
        </inertial>
        <self_collide>0</self_collide>
        <enable_wind>0</enable_wind>
        <kinematic>0</kinematic>
      </link>
      <joint name='iris_demo::iris::iris/ground_truth/odometry_sensorgt_joint' type='revolute'>
        <child>iris_demo::iris::iris/ground_truth/odometry_sensorgt_link</child>
        <parent>iris_demo::iris::base_link</parent>
        <axis>
          <xyz>0 0 1</xyz>
          <limit>
            <lower>0</lower>
            <upper>0</upper>
            <effort>0</effort>
            <velocity>0</velocity>
          </limit>
          <dynamics>
            <damping>1</damping>
            <spring_reference>0</spring_reference>
            <spring_stiffness>0</spring_stiffness>
          </dynamics>
          <use_parent_model_frame>1</use_parent_model_frame>
        </axis>
        <physics>
          <ode>
            <implicit_spring_damper>1</implicit_spring_damper>
            <limit>
              <cfm>0</cfm>
              <erp>0.2</erp>
            </limit>
          </ode>
        </physics>
      </joint>
      <link name='iris_demo::iris::iris/imu_link'>
        <inertial>
          <pose frame=''>0 0 0 0 -0 0</pose>
          <mass>0.15</mass>
          <inertia>
            <ixx>1e-05</ixx>
            <ixy>0</ixy>
            <ixz>0</ixz>
            <iyy>2e-05</iyy>
            <iyz>0</iyz>
            <izz>2e-05</izz>
          </inertia>
        </inertial>
        <sensor name='imu_sensor' type='imu'>
          <pose frame=''>0 0 0 -3.14159 -0 0</pose>
          <always_on>1</always_on>
          <update_rate>1000</update_rate>
          <imu/>
        </sensor>
        <pose frame=''>0 0 0.194923 0 -0 0</pose>
        <self_collide>0</self_collide>
        <enable_wind>0</enable_wind>
        <kinematic>0</kinematic>
      </link>
      <joint name='iris_demo::iris::iris/imu_joint' type='revolute'>
        <child>iris_demo::iris::iris/imu_link</child>
        <parent>iris_demo::iris::base_link</parent>
        <axis>
          <xyz>0 0 1</xyz>
          <limit>
            <lower>0</lower>
            <upper>0</upper>
            <effort>0</effort>
            <velocity>0</velocity>
          </limit>
          <dynamics>
            <damping>1</damping>
            <spring_reference>0</spring_reference>
            <spring_stiffness>0</spring_stiffness>
          </dynamics>
          <use_parent_model_frame>1</use_parent_model_frame>
        </axis>
        <physics>
          <ode>
            <implicit_spring_damper>1</implicit_spring_damper>
            <limit>
              <cfm>0</cfm>
              <erp>0.2</erp>
            </limit>
          </ode>
        </physics>
      </joint>
      <link name='iris_demo::iris::rotor_0'>
        <pose frame=''>0.13 -0.22 0.217923 0 -0 0</pose>
        <inertial>
          <pose frame=''>0 0 0 0 -0 0</pose>
          <mass>0.025</mass>
          <inertia>
            <ixx>9.75e-06</ixx>
            <ixy>0</ixy>
            <ixz>0</ixz>
            <iyy>0.000166704</iyy>
            <iyz>0</iyz>
            <izz>0.000167604</izz>
          </inertia>
        </inertial>
        <collision name='rotor_0_collision'>
          <pose frame=''>0 0 0 0 -0 0</pose>
          <geometry>
            <cylinder>
              <length>0.005</length>
              <radius>0.1</radius>
            </cylinder>
          </geometry>
          <surface>
            <contact>
              <ode/>
            </contact>
            <friction>
              <ode/>
              <torsional>
                <ode/>
              </torsional>
            </friction>
            <bounce/>
          </surface>
          <max_contacts>10</max_contacts>
        </collision>
        <visual name='rotor_0_visual'>
          <pose frame=''>0 0 0 0 -0 0</pose>
          <geometry>
            <mesh>
              <scale>1 1 1</scale>
              <uri>model://iris_with_standoffs/meshes/iris_prop_ccw.dae</uri>
            </mesh>
          </geometry>
          <material>
            <script>
              <name>Gazebo/Blue</name>
              <uri>__default__</uri>
            </script>
          </material>
        </visual>
        <gravity>1</gravity>
        <velocity_decay/>
        <self_collide>0</self_collide>
        <enable_wind>0</enable_wind>
        <kinematic>0</kinematic>
      </link>
      <joint name='iris_demo::iris::rotor_0_joint' type='revolute'>
        <child>iris_demo::iris::rotor_0</child>
        <parent>iris_demo::iris::base_link</parent>
        <axis>
          <xyz>0 0 1</xyz>
          <limit>
            <lower>-1e+16</lower>
            <upper>1e+16</upper>
          </limit>
          <dynamics>
            <damping>0.004</damping>
            <spring_reference>0</spring_reference>
            <spring_stiffness>0</spring_stiffness>
          </dynamics>
          <use_parent_model_frame>1</use_parent_model_frame>
        </axis>
        <physics>
          <ode>
            <implicit_spring_damper>1</implicit_spring_damper>
            <limit>
              <cfm>0</cfm>
              <erp>0.2</erp>
            </limit>
          </ode>
        </physics>
      </joint>
      <link name='iris_demo::iris::rotor_1'>
        <pose frame=''>-0.13 0.2 0.217923 0 -0 0</pose>
        <inertial>
          <pose frame=''>0 0 0 0 -0 0</pose>
          <mass>0.025</mass>
          <inertia>
            <ixx>9.75e-06</ixx>
            <ixy>0</ixy>
            <ixz>0</ixz>
            <iyy>0.000166704</iyy>
            <iyz>0</iyz>
            <izz>0.000167604</izz>
          </inertia>
        </inertial>
        <collision name='rotor_1_collision'>
          <pose frame=''>0 0 0 0 -0 0</pose>
          <geometry>
            <cylinder>
              <length>0.005</length>
              <radius>0.1</radius>
            </cylinder>
          </geometry>
          <surface>
            <contact>
              <ode/>
            </contact>
            <friction>
              <ode/>
              <torsional>
                <ode/>
              </torsional>
            </friction>
            <bounce/>
          </surface>
          <max_contacts>10</max_contacts>
        </collision>
        <visual name='rotor_1_visual'>
          <pose frame=''>0 0 0 0 -0 0</pose>
          <geometry>
            <mesh>
              <scale>1 1 1</scale>
              <uri>model://iris_with_standoffs/meshes/iris_prop_ccw.dae</uri>
            </mesh>
          </geometry>
          <material>
            <script>
              <name>Gazebo/DarkGrey</name>
              <uri>__default__</uri>
            </script>
          </material>
        </visual>
        <gravity>1</gravity>
        <velocity_decay/>
        <self_collide>0</self_collide>
        <enable_wind>0</enable_wind>
        <kinematic>0</kinematic>
      </link>
      <joint name='iris_demo::iris::rotor_1_joint' type='revolute'>
        <child>iris_demo::iris::rotor_1</child>
        <parent>iris_demo::iris::base_link</parent>
        <axis>
          <xyz>0 0 1</xyz>
          <limit>
            <lower>-1e+16</lower>
            <upper>1e+16</upper>
          </limit>
          <dynamics>
            <damping>0.004</damping>
            <spring_reference>0</spring_reference>
            <spring_stiffness>0</spring_stiffness>
          </dynamics>
          <use_parent_model_frame>1</use_parent_model_frame>
        </axis>
        <physics>
          <ode>
            <implicit_spring_damper>1</implicit_spring_damper>
            <limit>
              <cfm>0</cfm>
              <erp>0.2</erp>
            </limit>
          </ode>
        </physics>
      </joint>
      <link name='iris_demo::iris::rotor_2'>
        <pose frame=''>0.13 0.22 0.217923 0 -0 0</pose>
        <inertial>
          <pose frame=''>0 0 0 0 -0 0</pose>
          <mass>0.025</mass>
          <inertia>
            <ixx>9.75e-06</ixx>
            <ixy>0</ixy>
            <ixz>0</ixz>
            <iyy>0.000166704</iyy>
            <iyz>0</iyz>
            <izz>0.000167604</izz>
          </inertia>
        </inertial>
        <collision name='rotor_2_collision'>
          <pose frame=''>0 0 0 0 -0 0</pose>
          <geometry>
            <cylinder>
              <length>0.005</length>
              <radius>0.1</radius>
            </cylinder>
          </geometry>
          <surface>
            <contact>
              <ode/>
            </contact>
            <friction>
              <ode/>
              <torsional>
                <ode/>
              </torsional>
            </friction>
            <bounce/>
          </surface>
          <max_contacts>10</max_contacts>
        </collision>
        <visual name='rotor_2_visual'>
          <pose frame=''>0 0 0 0 -0 0</pose>
          <geometry>
            <mesh>
              <scale>1 1 1</scale>
              <uri>model://iris_with_standoffs/meshes/iris_prop_cw.dae</uri>
            </mesh>
          </geometry>
          <material>
            <script>
              <name>Gazebo/Blue</name>
              <uri>__default__</uri>
            </script>
          </material>
        </visual>
        <gravity>1</gravity>
        <velocity_decay/>
        <self_collide>0</self_collide>
        <enable_wind>0</enable_wind>
        <kinematic>0</kinematic>
      </link>
      <joint name='iris_demo::iris::rotor_2_joint' type='revolute'>
        <child>iris_demo::iris::rotor_2</child>
        <parent>iris_demo::iris::base_link</parent>
        <axis>
          <xyz>0 0 1</xyz>
          <limit>
            <lower>-1e+16</lower>
            <upper>1e+16</upper>
          </limit>
          <dynamics>
            <damping>0.004</damping>
            <spring_reference>0</spring_reference>
            <spring_stiffness>0</spring_stiffness>
          </dynamics>
          <use_parent_model_frame>1</use_parent_model_frame>
        </axis>
        <physics>
          <ode>
            <implicit_spring_damper>1</implicit_spring_damper>
            <limit>
              <cfm>0</cfm>
              <erp>0.2</erp>
            </limit>
          </ode>
        </physics>
      </joint>
      <link name='iris_demo::iris::rotor_3'>
        <pose frame=''>-0.13 -0.2 0.217923 0 -0 0</pose>
        <inertial>
          <pose frame=''>0 0 0 0 -0 0</pose>
          <mass>0.025</mass>
          <inertia>
            <ixx>9.75e-06</ixx>
            <ixy>0</ixy>
            <ixz>0</ixz>
            <iyy>0.000166704</iyy>
            <iyz>0</iyz>
            <izz>0.000167604</izz>
          </inertia>
        </inertial>
        <collision name='rotor_3_collision'>
          <pose frame=''>0 0 0 0 -0 0</pose>
          <geometry>
            <cylinder>
              <length>0.005</length>
              <radius>0.1</radius>
            </cylinder>
          </geometry>
          <surface>
            <contact>
              <ode/>
            </contact>
            <friction>
              <ode/>
              <torsional>
                <ode/>
              </torsional>
            </friction>
            <bounce/>
          </surface>
          <max_contacts>10</max_contacts>
        </collision>
        <visual name='rotor_3_visual'>
          <pose frame=''>0 0 0 0 -0 0</pose>
          <geometry>
            <mesh>
              <scale>1 1 1</scale>
              <uri>model://iris_with_standoffs/meshes/iris_prop_cw.dae</uri>
            </mesh>
          </geometry>
          <material>
            <script>
              <name>Gazebo/DarkGrey</name>
              <uri>__default__</uri>
            </script>
          </material>
        </visual>
        <gravity>1</gravity>
        <velocity_decay/>
        <self_collide>0</self_collide>
        <enable_wind>0</enable_wind>
        <kinematic>0</kinematic>
      </link>
      <joint name='iris_demo::iris::rotor_3_joint' type='revolute'>
        <child>iris_demo::iris::rotor_3</child>
        <parent>iris_demo::iris::base_link</parent>
        <axis>
          <xyz>0 0 1</xyz>
          <limit>
            <lower>-1e+16</lower>
            <upper>1e+16</upper>
          </limit>
          <dynamics>
            <damping>0.004</damping>
            <spring_reference>0</spring_reference>
            <spring_stiffness>0</spring_stiffness>
          </dynamics>
          <use_parent_model_frame>1</use_parent_model_frame>
        </axis>
        <physics>
          <ode>
            <implicit_spring_damper>1</implicit_spring_damper>
            <limit>
              <cfm>0</cfm>
              <erp>0.2</erp>
            </limit>
          </ode>
        </physics>
      </joint>
      <static>0</static>
      <link name='iris_demo::gimbal_small_2d::base_link'>
        <inertial>
          <mass>0.2</mass>
          <inertia>
            <ixx>0.0001</ixx>
            <ixy>0</ixy>
            <ixz>0</ixz>
            <iyy>0.0001</iyy>
            <iyz>0</iyz>
            <izz>0.0001</izz>
          </inertia>
        </inertial>
        <visual name='base_main_viz'>
          <geometry>
            <mesh>
              <scale>0.001 0.001 0.001</scale>
              <uri>model://gimbal_small_2d/meshes/base_main.dae</uri>
            </mesh>
          </geometry>
          <material>
            <script>
              <uri>file://media/materials/scripts/gazebo.material</uri>
              <name>Gazebo/FlatBlack</name>
            </script>
          </material>
        </visual>
        <visual name='base_arm_viz'>
          <geometry>
            <mesh>
              <scale>0.001 0.001 0.001</scale>
              <uri>model://gimbal_small_2d/meshes/base_arm.dae</uri>
            </mesh>
          </geometry>
          <material>
            <script>
              <uri>file://media/materials/scripts/gazebo.material</uri>
              <name>Gazebo/FlatBlack</name>
            </script>
          </material>
        </visual>
        <collision name='base_col'>
          <pose frame=''>0.01 0.075 -0.025 0 -0 0</pose>
          <geometry>
            <box>
              <size>0.1 0.05 0.15</size>
            </box>
          </geometry>
          <surface>
            <friction>
              <ode>
                <mu>1</mu>
                <mu2>1</mu2>
                <fdir1>0 0 0</fdir1>
                <slip1>0</slip1>
                <slip2>0</slip2>
              </ode>
              <torsional>
                <ode/>
              </torsional>
            </friction>
            <contact>
              <ode/>
            </contact>
            <bounce/>
          </surface>
          <max_contacts>10</max_contacts>
        </collision>
        <pose frame=''>0 -0.01 0.07 1.57 -0 1.57</pose>
        <self_collide>0</self_collide>
        <enable_wind>0</enable_wind>
        <kinematic>0</kinematic>
      </link>
      <link name='iris_demo::gimbal_small_2d::tilt_link'>
        <inertial>
          <mass>0.01</mass>
          <inertia>
            <ixx>1e-05</ixx>
            <ixy>0</ixy>
            <ixz>0</ixz>
            <iyy>1e-05</iyy>
            <iyz>0</iyz>
            <izz>1e-05</izz>
          </inertia>
        </inertial>
        <visual name='tilt_viz'>
          <pose frame=''>0 0 -0.005 0 -0 0</pose>
          <geometry>
            <mesh>
              <scale>0.001 0.001 0.001</scale>
              <uri>model://gimbal_small_2d/meshes/tilt.dae</uri>
            </mesh>
          </geometry>
          <material>
            <script>
              <uri>file://media/materials/scripts/gazebo.material</uri>
              <name>Gazebo/Grey</name>
            </script>
          </material>
        </visual>
        <collision name='tilt_col'>
          <pose frame=''>0 0 -0.005 0 -0 0</pose>
          <geometry>
            <mesh>
              <scale>0.001 0.001 0.001</scale>
              <uri>model://gimbal_small_2d/meshes/tilt.dae</uri>
            </mesh>
          </geometry>
          <max_contacts>10</max_contacts>
          <surface>
            <contact>
              <ode/>
            </contact>
            <bounce/>
            <friction>
              <torsional>
                <ode/>
              </torsional>
              <ode/>
            </friction>
          </surface>
        </collision>
        <visual name='camera_viz'>
          <pose frame=''>0 0 0.02 0 -0 0</pose>
          <geometry>
            <cylinder>
              <radius>0.025</radius>
              <length>0.05</length>
            </cylinder>
          </geometry>
          <material>
            <script>
              <uri>file://media/materials/scripts/gazebo.material</uri>
              <name>Gazebo/Grey</name>
            </script>
          </material>
        </visual>
        <collision name='camera_col'>
          <pose frame=''>0 0 0.02 0 -0 0</pose>
          <geometry>
            <cylinder>
              <radius>0.025</radius>
              <length>0.05</length>
            </cylinder>
          </geometry>
          <max_contacts>10</max_contacts>
          <surface>
            <contact>
              <ode/>
            </contact>
            <bounce/>
            <friction>
              <torsional>
                <ode/>
              </torsional>
              <ode/>
            </friction>
          </surface>
        </collision>
        <sensor name='camera' type='camera'>
          <pose frame=''>0 0 0 -1.57 -1.57 0</pose>
          <camera name='__default__'>
            <horizontal_fov>2</horizontal_fov>
            <image>
              <width>640</width>
              <height>480</height>
            </image>
            <clip>
              <near>0.05</near>
              <far>15000</far>
            </clip>
          </camera>
          <always_on>1</always_on>
          <update_rate>10</update_rate>
          <visualize>1</visualize>
        </sensor>
        <pose frame=''>0 -0.01 0.07 1.57 -0 1.57</pose>
        <self_collide>0</self_collide>
        <enable_wind>0</enable_wind>
        <kinematic>0</kinematic>
      </link>
      <joint name='iris_demo::gimbal_small_2d::tilt_joint' type='revolute'>
        <parent>iris_demo::gimbal_small_2d::base_link</parent>
        <child>iris_demo::gimbal_small_2d::tilt_link</child>
        <physics>
          <ode>
            <implicit_spring_damper>1</implicit_spring_damper>
            <limit>
              <cfm>0</cfm>
              <erp>0.2</erp>
            </limit>
          </ode>
        </physics>
        <axis>
          <xyz>0.000796 1 0</xyz>
          <dynamics>
            <damping>0.5</damping>
            <spring_reference>0</spring_reference>
            <spring_stiffness>0</spring_stiffness>
          </dynamics>
          <use_parent_model_frame>1</use_parent_model_frame>
          <limit>
            <lower>-0.1</lower>
            <upper>3.14159</upper>
            <effort>10</effort>
            <velocity>-1</velocity>
          </limit>
        </axis>
        <pose frame=''>0 0 0.02 0 -0 0</pose>
      </joint>
      <plugin name='gimbal_small_2d' filename='libGimbalSmall2dPlugin.so'>
        <joint>iris_demo::gimbal_small_2d::tilt_joint</joint>
      </plugin>
      <joint name='iris_demo::iris_gimbal_mount' type='revolute'>
        <parent>iris_demo::iris::base_link</parent>
        <child>iris_demo::gimbal_small_2d::base_link</child>
        <axis>
          <limit>
            <lower>0</lower>
            <upper>0</upper>
          </limit>
          <xyz>0 0 1</xyz>
          <use_parent_model_frame>1</use_parent_model_frame>
          <dynamics>
            <spring_reference>0</spring_reference>
            <spring_stiffness>0</spring_stiffness>
          </dynamics>
        </axis>
      </joint>
      <plugin name='rotor_0_blade_1' filename='libLiftDragPlugin.so'>
        <a0>0.3</a0>
        <alpha_stall>1.4</alpha_stall>
        <cla>4.2500</cla>
        <cda>0.10</cda>
        <cma>0.00</cma>
        <cla_stall>-0.025</cla_stall>
        <cda_stall>0.0</cda_stall>
        <cma_stall>0.0</cma_stall>
        <area>0.002</area>
        <air_density>1.2041</air_density>
        <cp>0.084 0 0</cp>
        <forward>0 1 0</forward>
        <upward>0 0 1</upward>
        <link_name>iris_demo::iris::rotor_0</link_name>
      </plugin>
      <plugin name='rotor_0_blade_2' filename='libLiftDragPlugin.so'>
        <a0>0.3</a0>
        <alpha_stall>1.4</alpha_stall>
        <cla>4.2500</cla>
        <cda>0.10</cda>
        <cma>0.00</cma>
        <cla_stall>-0.025</cla_stall>
        <cda_stall>0.0</cda_stall>
        <cma_stall>0.0</cma_stall>
        <area>0.002</area>
        <air_density>1.2041</air_density>
        <cp>-0.084 0 0</cp>
        <forward>0 -1 0</forward>
        <upward>0 0 1</upward>
        <link_name>iris_demo::iris::rotor_0</link_name>
      </plugin>
      <plugin name='rotor_1_blade_1' filename='libLiftDragPlugin.so'>
        <a0>0.3</a0>
        <alpha_stall>1.4</alpha_stall>
        <cla>4.2500</cla>
        <cda>0.10</cda>
        <cma>0.00</cma>
        <cla_stall>-0.025</cla_stall>
        <cda_stall>0.0</cda_stall>
        <cma_stall>0.0</cma_stall>
        <area>0.002</area>
        <air_density>1.2041</air_density>
        <cp>0.084 0 0</cp>
        <forward>0 1 0</forward>
        <upward>0 0 1</upward>
        <link_name>iris_demo::iris::rotor_1</link_name>
      </plugin>
      <plugin name='rotor_1_blade_2' filename='libLiftDragPlugin.so'>
        <a0>0.3</a0>
        <alpha_stall>1.4</alpha_stall>
        <cla>4.2500</cla>
        <cda>0.10</cda>
        <cma>0.00</cma>
        <cla_stall>-0.025</cla_stall>
        <cda_stall>0.0</cda_stall>
        <cma_stall>0.0</cma_stall>
        <area>0.002</area>
        <air_density>1.2041</air_density>
        <cp>-0.084 0 0</cp>
        <forward>0 -1 0</forward>
        <upward>0 0 1</upward>
        <link_name>iris_demo::iris::rotor_1</link_name>
      </plugin>
      <plugin name='rotor_2_blade_1' filename='libLiftDragPlugin.so'>
        <a0>0.3</a0>
        <alpha_stall>1.4</alpha_stall>
        <cla>4.2500</cla>
        <cda>0.10</cda>
        <cma>0.00</cma>
        <cla_stall>-0.025</cla_stall>
        <cda_stall>0.0</cda_stall>
        <cma_stall>0.0</cma_stall>
        <area>0.002</area>
        <air_density>1.2041</air_density>
        <cp>0.084 0 0</cp>
        <forward>0 -1 0</forward>
        <upward>0 0 1</upward>
        <link_name>iris_demo::iris::rotor_2</link_name>
      </plugin>
      <plugin name='rotor_2_blade_2' filename='libLiftDragPlugin.so'>
        <a0>0.3</a0>
        <alpha_stall>1.4</alpha_stall>
        <cla>4.2500</cla>
        <cda>0.10</cda>
        <cma>0.00</cma>
        <cla_stall>-0.025</cla_stall>
        <cda_stall>0.0</cda_stall>
        <cma_stall>0.0</cma_stall>
        <area>0.002</area>
        <air_density>1.2041</air_density>
        <cp>-0.084 0 0</cp>
        <forward>0 1 0</forward>
        <upward>0 0 1</upward>
        <link_name>iris_demo::iris::rotor_2</link_name>
      </plugin>
      <plugin name='rotor_3_blade_1' filename='libLiftDragPlugin.so'>
        <a0>0.3</a0>
        <alpha_stall>1.4</alpha_stall>
        <cla>4.2500</cla>
        <cda>0.10</cda>
        <cma>0.00</cma>
        <cla_stall>-0.025</cla_stall>
        <cda_stall>0.0</cda_stall>
        <cma_stall>0.0</cma_stall>
        <area>0.002</area>
        <air_density>1.2041</air_density>
        <cp>0.084 0 0</cp>
        <forward>0 -1 0</forward>
        <upward>0 0 1</upward>
        <link_name>iris_demo::iris::rotor_3</link_name>
      </plugin>
      <plugin name='rotor_3_blade_2' filename='libLiftDragPlugin.so'>
        <a0>0.3</a0>
        <alpha_stall>1.4</alpha_stall>
        <cla>4.2500</cla>
        <cda>0.10</cda>
        <cma>0.00</cma>
        <cla_stall>-0.025</cla_stall>
        <cda_stall>0.0</cda_stall>
        <cma_stall>0.0</cma_stall>
        <area>0.002</area>
        <air_density>1.2041</air_density>
        <cp>-0.084 0 0</cp>
        <forward>0 1 0</forward>
        <upward>0 0 1</upward>
        <link_name>iris_demo::iris::rotor_3</link_name>
      </plugin>
      <plugin name='arducopter_plugin' filename='libArduPilotPlugin.so'>
        <fdm_addr>127.0.0.1</fdm_addr>
        <fdm_port_in>9002</fdm_port_in>
        <fdm_port_out>9003</fdm_port_out>
        <modelXYZToAirplaneXForwardZDown>0 0 0 3.141593 0 0</modelXYZToAirplaneXForwardZDown>
        <gazeboXYZToNED>0 0 0 3.141593 0 0</gazeboXYZToNED>
        <imuName>iris_demo::iris::iris/imu_link::imu_sensor</imuName>
        <connectionTimeoutMaxCount>5</connectionTimeoutMaxCount>
        <control channel='0'>
          <type>VELOCITY</type>
          <offset>0</offset>
          <p_gain>0.20</p_gain>
          <i_gain>0</i_gain>
          <d_gain>0</d_gain>
          <i_max>0</i_max>
          <i_min>0</i_min>
          <cmd_max>2.5</cmd_max>
          <cmd_min>-2.5</cmd_min>
          <jointName>iris_demo::iris::rotor_0_joint</jointName>
          <multiplier>838</multiplier>
          <controlVelocitySlowdownSim>1</controlVelocitySlowdownSim>
        </control>
        <control channel='1'>
          <type>VELOCITY</type>
          <offset>0</offset>
          <p_gain>0.20</p_gain>
          <i_gain>0</i_gain>
          <d_gain>0</d_gain>
          <i_max>0</i_max>
          <i_min>0</i_min>
          <cmd_max>2.5</cmd_max>
          <cmd_min>-2.5</cmd_min>
          <jointName>iris_demo::iris::rotor_1_joint</jointName>
          <multiplier>838</multiplier>
          <controlVelocitySlowdownSim>1</controlVelocitySlowdownSim>
        </control>
        <control channel='2'>
          <type>VELOCITY</type>
          <offset>0</offset>
          <p_gain>0.20</p_gain>
          <i_gain>0</i_gain>
          <d_gain>0</d_gain>
          <i_max>0</i_max>
          <i_min>0</i_min>
          <cmd_max>2.5</cmd_max>
          <cmd_min>-2.5</cmd_min>
          <jointName>iris_demo::iris::rotor_2_joint</jointName>
          <multiplier>-838</multiplier>
          <controlVelocitySlowdownSim>1</controlVelocitySlowdownSim>
        </control>
        <control channel='3'>
          <type>VELOCITY</type>
          <offset>0</offset>
          <p_gain>0.20</p_gain>
          <i_gain>0</i_gain>
          <d_gain>0</d_gain>
          <i_max>0</i_max>
          <i_min>0</i_min>
          <cmd_max>2.5</cmd_max>
          <cmd_min>-2.5</cmd_min>
          <jointName>iris_demo::iris::rotor_3_joint</jointName>
          <multiplier>-838</multiplier>
          <controlVelocitySlowdownSim>1</controlVelocitySlowdownSim>
        </control>
      </plugin>
      <link name='lidar::lidar_link'>
        <visual name='visual'>
          <geometry>
            <cylinder>
              <radius>0.01</radius>
              <length>0.02</length>
            </cylinder>
          </geometry>
        </visual>
        <inertial>
          <mass>1e-16</mass>
          <inertia>
            <ixx>1e-16</ixx>
            <ixy>0</ixy>
            <ixz>0</ixz>
            <iyy>1e-16</iyy>
            <iyz>0</iyz>
            <izz>1e-16</izz>
          </inertia>
        </inertial>
        <sensor name='sensor' type='ray'>
          <pose frame=''>0 0 0 3.14159 1.57079 3.14159</pose>
          <visualize>1</visualize>
          <update_rate>30</update_rate>
          <ray>
            <scan>
              <horizontal>
                <samples>1</samples>
                <resolution>1</resolution>
                <min_angle>0</min_angle>
                <max_angle>0</max_angle>
              </horizontal>
              <vertical>
                <samples>1</samples>
                <min_angle>0</min_angle>
                <max_angle>0</max_angle>
              </vertical>
            </scan>
            <range>
              <min>0.055</min>
              <max>50</max>
              <resolution>0.02</resolution>
            </range>
          </ray>
        </sensor>
        <pose frame=''>-0.05 0 0.05 0 -0 0</pose>
        <self_collide>0</self_collide>
        <enable_wind>0</enable_wind>
        <kinematic>0</kinematic>
      </link>
      <link name='lidar_360::lidar_360_link'>
        <visual name='visual'>
          <geometry>
            <cylinder>
              <radius>0.01</radius>
              <length>0.03</length>
            </cylinder>
          </geometry>
        </visual>
        <inertial>
          <mass>1e-16</mass>
          <inertia>
            <ixx>1e-16</ixx>
            <ixy>0</ixy>
            <ixz>0</ixz>
            <iyy>1e-16</iyy>
            <iyz>0</iyz>
            <izz>1e-16</izz>
          </inertia>
        </inertial>
        <sensor name='sensor' type='ray'>
          <pose frame=''>0 0 0.01 0 -0 0</pose>
          <visualize>1</visualize>
          <update_rate>1</update_rate>
          <ray>
            <scan>
              <horizontal>
                <samples>8</samples>
                <resolution>1</resolution>
                <min_angle>0</min_angle>
                <max_angle>-5.49779</max_angle>
              </horizontal>
              <vertical>
                <samples>1</samples>
                <min_angle>0</min_angle>
                <max_angle>0</max_angle>
              </vertical>
            </scan>
            <range>
              <min>0.35</min>
              <max>50</max>
              <resolution>0.02</resolution>
            </range>
          </ray>
          <plugin name='sensor_plugin' filename='libgazebo_ros_laser.so'>
            <topicName>/mavros/obstacle/send</topicName>
            <frameName>lidar_360</frameName>
          </plugin>
        </sensor>
        <pose frame=''>0 0 0.25 0 -0 0</pose>
        <self_collide>0</self_collide>
        <enable_wind>0</enable_wind>
        <kinematic>0</kinematic>
      </link>
      <joint name='iris_lidar_mount' type='revolute'>
        <parent>iris_demo::gimbal_small_2d::base_link</parent>
        <child>lidar::lidar_link</child>
        <axis>
          <xyz>0 0 0</xyz>
          <limit>
            <lower>0</lower>
            <upper>0</upper>
          </limit>
          <use_parent_model_frame>0</use_parent_model_frame>
          <dynamics>
            <spring_reference>0</spring_reference>
            <spring_stiffness>0</spring_stiffness>
          </dynamics>
        </axis>
        <pose frame=''>0 0 0.01 0 -0 0</pose>
      </joint>
      <joint name='iris_lidar_360_mount' type='revolute'>
        <parent>iris_demo::iris::base_link</parent>
        <child>lidar_360::lidar_360_link</child>
        <axis>
          <xyz>0 0 0</xyz>
          <limit>
            <lower>0</lower>
            <upper>0</upper>
          </limit>
          <use_parent_model_frame>0</use_parent_model_frame>
          <dynamics>
            <spring_reference>0</spring_reference>
            <spring_stiffness>0</spring_stiffness>
          </dynamics>
        </axis>
        <pose frame=''>0 0 -0.01 0 -0 0</pose>
      </joint>
      <pose frame=''>0 0 0 0 -0 0</pose>
    </model>
    <model name='a1'>
      <static>1</static>
      <link name='link'>
        <pose frame=''>0 0 5 0 -0 0</pose>
        <collision name='collision'>
          <geometry>
            <box>
              <size>40 10 10</size>
            </box>
          </geometry>
          <max_contacts>10</max_contacts>
          <surface>
            <contact>
              <ode/>
            </contact>
            <bounce/>
            <friction>
              <torsional>
                <ode/>
              </torsional>
              <ode/>
            </friction>
          </surface>
        </collision>
        <visual name='visual'>
          <geometry>
            <box>
              <size>40 10 10</size>
            </box>
          </geometry>
        </visual>
        <self_collide>0</self_collide>
        <enable_wind>0</enable_wind>
        <kinematic>0</kinematic>
      </link>
      <pose frame=''>15 -30 -9 0 -0 0</pose>
    </model>
    <model name='a2'>
      <static>1</static>
      <link name='link'>
        <pose frame=''>0 0 5 0 -0 0</pose>
        <collision name='collision'>
          <geometry>
            <box>
              <size>10 50 10</size>
            </box>
          </geometry>
          <max_contacts>10</max_contacts>
          <surface>
            <contact>
              <ode/>
            </contact>
            <bounce/>
            <friction>
              <torsional>
                <ode/>
              </torsional>
              <ode/>
            </friction>
          </surface>
        </collision>
        <visual name='visual'>
          <geometry>
            <box>
              <size>10 50 10</size>
            </box>
          </geometry>
        </visual>
        <self_collide>0</self_collide>
        <enable_wind>0</enable_wind>
        <kinematic>0</kinematic>
      </link>
      <pose frame=''>30 0 0 0 -0 0</pose>
    </model>
    <model name='a3'>
      <static>1</static>
      <link name='link'>
        <pose frame=''>0 0 5 0 -0 0</pose>
        <collision name='collision'>
          <geometry>
            <box>
              <size>70 10 10</size>
            </box>
          </geometry>
          <max_contacts>10</max_contacts>
          <surface>
            <contact>
              <ode/>
            </contact>
            <bounce/>
            <friction>
              <torsional>
                <ode/>
              </torsional>
              <ode/>
            </friction>
          </surface>
        </collision>
        <visual name='visual'>
          <geometry>
            <box>
              <size>70 10 10</size>
            </box>
          </geometry>
        </visual>
        <self_collide>0</self_collide>
        <enable_wind>0</enable_wind>
        <kinematic>0</kinematic>
      </link>
      <pose frame=''>0 30 0 0 -0 0</pose>
    </model>
    <model name='a4'>
      <static>1</static>
      <link name='link'>
        <pose frame=''>0 0 5 0 -0 0</pose>
        <collision name='collision'>
          <geometry>
            <box>
              <size>10 70 10</size>
            </box>
          </geometry>
          <max_contacts>10</max_contacts>
          <surface>
            <contact>
              <ode/>
            </contact>
            <bounce/>
            <friction>
              <torsional>
                <ode/>
              </torsional>
              <ode/>
            </friction>
          </surface>
        </collision>
        <visual name='visual'>
          <geometry>
            <box>
              <size>10 70 10</size>
            </box>
          </geometry>
        </visual>
        <self_collide>0</self_collide>
        <enable_wind>0</enable_wind>
        <kinematic>0</kinematic>
      </link>
      <pose frame=''>-30 0 0 0 -0 0</pose>
    </model>
    <model name='a5'>
      <static>1</static>
      <link name='link'>
        <pose frame=''>0 0 5 0 -0 0</pose>
        <collision name='collision'>
          <geometry>
            <box>
              <size>20 10 10</size>
            </box>
          </geometry>
          <max_contacts>10</max_contacts>
          <surface>
            <contact>
              <ode/>
            </contact>
            <bounce/>
            <friction>
              <torsional>
                <ode/>
              </torsional>
              <ode/>
            </friction>
          </surface>
        </collision>
        <visual name='visual'>
          <geometry>
            <box>
              <size>20 10 10</size>
            </box>
          </geometry>
        </visual>
        <self_collide>0</self_collide>
        <enable_wind>0</enable_wind>
        <kinematic>0</kinematic>
      </link>
      <pose frame=''>-15 -30 0 0 -0 0</pose>
    </model>
    <gravity>0 0 -9.8</gravity>
    <magnetic_field>6e-06 2.3e-05 -4.2e-05</magnetic_field>
    <atmosphere type='adiabatic'/>
    <physics name='default_physics' default='0' type='ode'>
      <max_step_size>0.001</max_step_size>
      <real_time_factor>1</real_time_factor>
      <real_time_update_rate>1000</real_time_update_rate>
    </physics>
    <audio>
      <device>default</device>
    </audio>
    <wind/>
    <spherical_coordinates>
      <surface_model>EARTH_WGS84</surface_model>
      <latitude_deg>0</latitude_deg>
      <longitude_deg>0</longitude_deg>
      <elevation>0</elevation>
      <heading_deg>0</heading_deg>
    </spherical_coordinates>
    <state world_name='default'>
      <sim_time>35 369000000</sim_time>
      <real_time>140 422484764</real_time>
      <wall_time>1591597874 877919880</wall_time>
      <iterations>35369</iterations>
      <model name='a1'>
        <pose frame=''>15 -30 0 0 -0 0</pose>
        <scale>1 1 1</scale>
        <link name='link'>
          <pose frame=''>15 -30 -4 0 -0 0</pose>
          <velocity>0 0 0 0 -0 0</velocity>
          <acceleration>0 0 0 0 -0 0</acceleration>
          <wrench>0 0 0 0 -0 0</wrench>
        </link>
      </model>
      <model name='a2'>
        <pose frame=''>30 0 0 0 -0 0</pose>
        <scale>1 1 1</scale>
        <link name='link'>
          <pose frame=''>30 0 -2 0 -0 0</pose>
          <velocity>0 0 0 0 -0 0</velocity>
          <acceleration>0 0 0 0 -0 0</acceleration>
          <wrench>0 0 0 0 -0 0</wrench>
        </link>
      </model>
      <model name='a3'>
        <pose frame=''>0 30 0 0 -0 0</pose>
        <scale>1 1 1</scale>
        <link name='link'>
          <pose frame=''>0 30 0 0 -0 0</pose>
          <velocity>0 0 0 0 -0 0</velocity>
          <acceleration>0 0 0 0 -0 0</acceleration>
          <wrench>0 0 0 0 -0 0</wrench>
        </link>
      </model>
      <model name='a4'>
        <pose frame=''>-30 0 0 0 -0 0</pose>
        <scale>1 1 1</scale>
        <link name='link'>
          <pose frame=''>-30 0 2 0 -0 0</pose>
          <velocity>0 0 0 0 -0 0</velocity>
          <acceleration>0 0 0 0 -0 0</acceleration>
          <wrench>0 0 0 0 -0 0</wrench>
        </link>
      </model>
      <model name='a5'>
        <pose frame=''>-15 -30 0 0 -0 0</pose>
        <scale>1 1 1</scale>
        <link name='link'>
          <pose frame=''>-15 -30 -2 0 -0 0</pose>
          <velocity>0 0 0 0 -0 0</velocity>
          <acceleration>0 0 0 0 -0 0</acceleration>
          <wrench>0 0 0 0 -0 0</wrench>
        </link>
      </model>
      <model name='ground_plane'>
        <pose frame=''>0 0 0 0 -0 0</pose>
        <scale>1 1 1</scale>
        <link name='link'>
          <pose frame=''>0 0 0 0 -0 0</pose>
          <velocity>0 0 0 0 -0 0</velocity>
          <acceleration>0 0 0 0 -0 0</acceleration>
          <wrench>0 0 0 0 -0 0</wrench>
        </link>
      </model>
      <model name='ground_plane2'>
        <pose frame=''>0 0 0 0 -0 0</pose>
        <scale>1 1 1</scale>
        <link name='link'>
          <pose frame=''>0 0 0 0 -0 0</pose>
          <velocity>0 0 0 0 -0 0</velocity>
          <acceleration>0 0 0 0 -0 0</acceleration>
          <wrench>0 0 0 0 -0 0</wrench>
        </link>
      </model>
      <model name='iris_lidar'>
        <pose frame=''>0 -1e-06 -0.000424 -0.002122 -0 1e-06</pose>
        <scale>1 1 1</scale>
        <link name='iris_demo::gimbal_small_2d::base_link'>
          <pose frame=''>0 -0.009852 0.069597 1.57 0.002122 1.57</pose>
          <velocity>-4e-06 1e-05 3.5e-05 -0.000144 1.2e-05 0.000118</velocity>
          <acceleration>-0.007036 0.000134 -0.000145 -0.001936 0.020161 0.227786</acceleration>
          <wrench>-0.001407 2.7e-05 -2.9e-05 0 -0 0</wrench>
        </link>
        <link name='iris_demo::gimbal_small_2d::tilt_link'>
          <pose frame=''>0.019984 -0.009826 0.089613 3.14079 0.002122 1.57</pose>
          <velocity>-4e-06 1.5e-05 3.5e-05 -0.000144 1.7e-05 0.000118</velocity>
          <acceleration>-0.006554 0.004728 -0.000594 -0.002059 0.027478 0.228078</acceleration>
          <wrench>-6.6e-05 4.7e-05 -6e-06 0 -0 0</wrench>
        </link>
        <link name='iris_demo::iris::base_link'>
          <pose frame=''>0 0.000413 0.194498 -0.002122 -0 1e-06</pose>
          <velocity>-1e-06 2.8e-05 3.4e-05 -0.000144 -4e-06 0</velocity>
          <acceleration>-0.001854 0.000382 -0.000165 -0.001956 -0.009441 6e-06</acceleration>
          <wrench>-0.00278 0.000573 -0.000248 0 -0 0</wrench>
        </link>
        <link name='iris_demo::iris::iris/ground_truth/odometry_sensorgt_link'>
          <pose frame=''>0 0.000413 0.194498 -0.002122 -0 1e-06</pose>
          <velocity>-2e-06 2.8e-05 3.4e-05 -0.000144 1.3e-05 0.000113</velocity>
          <acceleration>-0.004586 0.000381 -0.000165 -0.001968 0.021612 0.225371</acceleration>
          <wrench>-0.000688 5.7e-05 -2.5e-05 0 -0 0</wrench>
        </link>
        <link name='iris_demo::iris::iris/imu_link'>
          <pose frame=''>0 0.000413 0.194498 -0.002122 -0 1e-06</pose>
          <velocity>-2e-06 2.8e-05 3.4e-05 -0.000144 1.3e-05 0.000113</velocity>
          <acceleration>-0.004466 0.000381 -0.000165 -0.001968 0.021616 0.225559</acceleration>
          <wrench>-0.00067 5.7e-05 -2.5e-05 0 -0 0</wrench>
        </link>
        <link name='iris_demo::iris::rotor_0'>
          <pose frame=''>0.130001 -0.219538 0.217965 -0.002122 -0 -6e-06</pose>
          <velocity>-3e-06 3.1e-05 6.4e-05 -0.000144 1.3e-05 0</velocity>
          <acceleration>-0.00658 -0.00119 -0.002479 -0.00197 0.021138 -0.000184</acceleration>
          <wrench>-0.000164 -3e-05 -6.2e-05 0 -0 0</wrench>
        </link>
        <link name='iris_demo::iris::rotor_1'>
          <pose frame=''>-0.13 0.200461 0.217074 -0.002122 -0 -3.6e-05</pose>
          <velocity>-1e-06 3.2e-05 6e-06 -0.000144 1.3e-05 -1e-06</velocity>
          <acceleration>-0.001472 0.001979 0.002199 -0.001965 0.021206 -0.000179</acceleration>
          <wrench>-3.7e-05 4.9e-05 5.5e-05 0 -0 0</wrench>
        </link>
        <link name='iris_demo::iris::rotor_2'>
          <pose frame=''>0.13 0.220461 0.217031 -0.002122 -0 -7e-06</pose>
          <velocity>-0 3.1e-05 0 -0.000144 1.3e-05 0</velocity>
          <acceleration>-0.001161 -0.001159 -0.00335 -0.001922 0.021253 -0.000182</acceleration>
          <wrench>-2.9e-05 -2.9e-05 -8.4e-05 0 -0 0</wrench>
        </link>
        <link name='iris_demo::iris::rotor_3'>
          <pose frame=''>-0.129999 -0.199538 0.217923 -0.002122 -0 -3.8e-05</pose>
          <velocity>-3e-06 3.2e-05 6.4e-05 -0.000144 1.3e-05 -1e-06</velocity>
          <acceleration>-0.00628 0.002048 0.002993 -0.001974 0.0213 -0.000184</acceleration>
          <wrench>-0.000157 5.1e-05 7.5e-05 0 -0 0</wrench>
        </link>
        <link name='lidar::lidar_link'>
          <pose frame=''>-0.05 0.000105 0.049576 -0.002122 -0 1e-06</pose>
          <velocity>-5e-06 1e-06 3.4e-05 -0.000144 1.3e-05 0.000118</velocity>
          <acceleration>-0.009439 -0.011316 0.000959 -0.001963 0.022471 0.22823</acceleration>
          <wrench>-0 -0 0 0 -0 0</wrench>
        </link>
        <link name='lidar_360::lidar_360_link'>
          <pose frame=''>0 0.00053 0.249575 -0.002122 -0 1e-06</pose>
          <velocity>-1e-06 3.6e-05 3.4e-05 -0.000144 1.2e-05 -7e-06</velocity>
          <acceleration>-0.003073 0.00049 -0.000166 -0.002015 0.019375 -0.011854</acceleration>
          <wrench>-0 0 -0 0 -0 0</wrench>
        </link>
      </model>
      <light name='sun'>
        <pose frame=''>0 0 10 0 -0 0</pose>
      </light>
    </state>
    <gui fullscreen='0'>
      <camera name='user_camera'>
        <pose frame=''>-38.9401 -62.0113 27.0771 -0 0.363642 0.388194</pose>
        <view_controller>orbit</view_controller>
        <projection_type>perspective</projection_type>
      </camera>
    </gui>
  </world>
</sdf>
